Workbook

Sheet NOVEMBER 2025
A1: LAPORAN KONSUMSI BBM KENDARAAN DINAS PT PELINDO DAYA SEJAHTERA
A2: PERIODE NOVEMBER 2025
A3: SUGENG | V3: MAS WAFI
A4: TANGGAL | B4: HANTARAN OPERATOR ITV TPS | L4: OPERASIONAL KEBERSHAN TPS | V4: SAPU JALAN PERAK BARAT | X4: PENYIRAMAN PERAK | Z4: SAPU JALAN (SPMT) | AB4: KEBERSIHAN PERAK | AD4: GRAND TOTAL
B5: L 1941 OL (L 1873 SB) | D5: L 1941 OL (L 1873 SB) | F5: L 1536 MZ (L 1388 PC) | H5: L 1536 MZ (L 1388 PC) | J5: L 1838 ZB (L 1641 PA) | L5: L 8203 AF | N5: L 9910 BR | P5: L 9910 BR | R5: L 9078 BU | T5: L 9078 BU | V5: pertalite | W5: L 9662 NK | X5: pertamax | Y5: L 9964 NK | Z5: Solar | AA5: AE 8719 SQ/L 8393 LT | AB5: pertalite | AC5: L 8065 TR
B6: Pertalite | C6: Rp | D6: Pertamax | E6: Rp | F6: Pertalite | G6: Rp | H6: Pertamax | I6: Rp | J6: Pertalite | K6: Rp | L6: solar | M6: Rp | N6: solar | O6: Rp | P6: pertamax | Q6: Rp | R6: Pertamax | S6: Rp | T6: Solar | U6: Rp | V6: Liter | W6: Rp | X6: Liter | Y6: Rp | Z6: Liter | AA6: Rp | AB6: Liter | AC6: Rp
A7: 45962
B10: 29.15 | C10: 291500 | J10: 39.27 | K10: 392700
A11: 45963
B14: 23.84 | C14: 238400 | F14: 39.89 | G14: 398900 | J14: 26.13 | K14: 261300
A15: 45964
F17: 27.06 | G17: 270600
B18: 24 | C18: 240000 | J18: 18.96 | K18: 189600 | P18: 20 | Q18: 244000 | T18: 59.47 | U18: 404396 | V18: 20 | W18: 200000
A19: 45965
J21: 26.13 | K21: 261300
B22: 15.11 | C22: 151100 | F22: 25.87 | G22: 258700 | V22: 20 | W22: 200000
A23: 45966
B25: 12.58 | C25: 125800 | AB25: 10 | AC25: 100000
F26: 26.75 | G26: 267500 | J26: 21.24 | K26: 212400
A27: 45967
F30: 29.71 | G30: 297100 | J30: 29.47 | K30: 294700
A31: 45968
B33: 18.9 | C33: 189000
F34: 25.46 | G34: 254600 | J34: 22.56 | K34: 225600 | L34: 55.65 | M34: 378420 | N34: 52.37 | O34: 356120 | R34: 20 | S34: 244000 | X34: 20 | Y34: 244000
A35: 45969
B38: 29.1 | C38: 291000 | F38: 26.45 | G38: 264500 | J38: 18.94 | K38: 189400 | T38: 51.02 | U38: 346936
A39: 45970
B42: 19.71 | C42: 197100 | F42: 31.67 | G42: 316700 | J42: 27.91 | K42: 279100
A43: 45971
B46: 21.88 | C46: 218800 | F46: 23.86 | G46: 238600 | J46: 16.73 | K46: 167300 | R46: 20 | S46: 244000
A47: 45972
F50: 25.2 | G50: 252000 | J50: 24.46 | K50: 244600 | V50: 20 | W50: 200000 | X50: 20 | Y50: 244000 | AB50: 10 | AC50: 100000
A51: 45973
B54: 24.58 | C54: 245800 | F54: 29.11 | G54: 291100 | J54: 24.31 | K54: 243100 | T54: 60 | U54: 408000 | Z54: 32.34 | AA54: 219912
A55: 45974
B58: 19.31 | C58: 193100 | F58: 24.56 | G58: 245600 | J58: 27 | K58: 270000
A59: 45975
B62: 13.64 | C62: 136400 | F62: 24.31 | G62: 243100 | J62: 25.76 | K62: 257600 | R62: 20 | S62: 244000 | X62: 20 | Y62: 244000 | AB62: 10 | AC62: 100000
A63: 45976
B66: 14.99 | C66: 149900 | F66: 28.02 | G66: 280200 | J66: 23.19 | K66: 231900
...

Sheet OKTOBER 2025
A1: LAPORAN KONSUMSI BBM KENDARAAN DINAS PT PELINDO DAYA SEJAHTERA
A2: PERIODE AGUSTUS 2025
A3: SUGENG | V3: MAS WAFI
A4: TANGGAL | B4: HANTARAN OPERATOR ITV TPS | L4: OPERASIONAL KEBERSHAN TPS | V4: SAPU JALAN PERAK BARAT | X4: PENYIRAMAN PERAK | Z4: SAPU JALAN (SPMT) | AB4: KEBERSIHAN PERAK | AD4: GRAND TOTAL
B5: L 1941 OL (L 1873 SB) | D5: L 1941 OL (L 1873 SB) | F5: L 1536 MZ (L 1388 PC) | H5: L 1536 MZ (L 1388 PC) | J5: L 1838 ZB (L 1641 PA) | L5: L 8203 AF | N5: L 9910 BR | P5: L 9910 BR | R5: L 9078 BU | T5: L 9078 BU | V5: pertalite | W5: L 9662 NK | X5: pertamax | Y5: L 9964 NK | Z5: Solar | AA5: AE 8719 SQ/L 8393 LT | AB5: pertalite | AC5: L 8065 TR
B6: Pertalite | C6: Rp | D6: Pertamax | E6: Rp | F6: Pertalite | G6: Rp | H6: Pertamax | I6: Rp | J6: Pertalite | K6: Rp | L6: solar | M6: Rp | N6: solar | O6: Rp | P6: pertamax | Q6: Rp | R6: Pertamax | S6: Rp | T6: Solar | U6: Rp | V6: Liter | W6: Rp | X6: Liter | Y6: Rp | Z6: Liter | AA6: Rp | AB6: Liter | AC6: Rp
A7: 45931
F8: 28.01 | G8: 280100
J9: 18.05 | K9: 180500
F10: 26.55 | G10: 265500 | V10: 20 | W10: 200000
A11: 45932 | AB11: 10 | AC11: 100000
B14: 22.84 | C14: 228400 | F14: 25.65 | G14: 256500 | J14: 21.2 | K14: 212000
A15: 45933
B18: 28.07 | C18: 280700 | D18: 20 | E18: 244000 | F18: 27.56 | G18: 275600 | J18: 13.2 | K18: 132000 | L18: 52.56 | M18: 357408 | T18: 60 | U18: 408000 | X18: 20 | Y18: 244000
A19: 45934
B22: 35.12 | C22: 351200 | F22: 29.86 | G22: 298600 | J22: 21.07 | K22: 210700
A23: 45935
B26: 26.92 | C26: 269200
A27: 45936
B30: 29.74 | C30: 297400 | F30: 28.13 | G30: 281300 | J30: 31.31 | K30: 313100 | V30: 20 | W30: 200000 | AB30: 10 | AC30: 100000
A31: 45937
B34: 28.62 | C34: 286200 | F34: 30.47 | G34: 304700 | P34: 20 | Q34: 244000
A35: 45938
B38: 33.11 | C38: 331100 | F38: 31.21 | G38: 312100 | J38: 25.36 | K38: 253600 | N38: 60 | O38: 408000 | V38: 20 | W38: 200000 | X38: 20 | Y38: 244000
A39: 45939
B42: 27.36 | C42: 273600 | F42: 29.94 | G42: 299400 | N42: 60 | O42: 408000
A43: 45940
B46: 21.77 | C46: 217700 | F46: 25.28 | G46: 252800 | AB46: 10 | AC46: 100000
A47: 45941
B50: 26.31 | C50: 263100 | F50: 29.6 | G50: 296000 | J50: 32.31 | K50: 323100
A51: 45942
B54: 34.09 | C54: 340900 | F54: 25.88 | G54: 258800 | Z54: 33.24 | AA54: 226032
A55: 45943
B58: 29.06 | C58: 290600 | F58: 31.45 | G58: 314500 | J58: 15.33 | K58: 153300 | P58: 20 | Q58: 244000 | T58: 65.12 | U58: 442816 | V58: 20 | W58: 200000
A59: 45944
B62: 30.61 | C62: 306100 | F62: 28.96 | G62: 289600 | X62: 20 | Y62: 244000 | AB62: 10 | AC62: 100000
A63: 45945
B66: 31.2 | C66: 312000 | F66: 29.63 | G66: 296300 | L66: 57.14 | M66: 388552
A67: 45946
B70: 30.4 | C70: 304000 | F70: 32.99 | G70: 329900
...

Sheet SEPTEMBER 2025
A1: LAPORAN KONSUMSI BBM KENDARAAN DINAS PT PELINDO DAYA SEJAHTERA
A2: PERIODE AGUSTUS 2025
A3: SUGENG | V3: MAS WAFI
A4: TANGGAL | B4: HANTARAN OPERATOR ITV TPS | L4: OPERASIONAL KEBERSHAN TPS | V4: SAPU JALAN PERAK BARAT | X4: PENYIRAMAN PERAK | Z4: SAPU JALAN (SPMT) | AB4: KEBERSIHAN PERAK | AD4: GRAND TOTAL
B5: L 1941 OL (L 1873 SB) | D5: L 1941 OL (L 1873 SB) | F5: L 1536 MZ (L 1388 PC) | H5: L 1536 MZ (L 1388 PC) | J5: L 1838 ZB (L 1641 PA) | L5: L 8203 AF | N5: L 9910 BR | P5: L 9910 BR | R5: L 9034 BU | T5: L 9078 BU | V5: pertalite | W5: L 9662 NK | X5: pertamax | Y5: L 9964 NK | Z5: Solar | AA5: AE 8719 SQ/L 8393 LT | AB5: pertalite | AC5: L 8065 TR
B6: Pertalite | C6: Rp | D6: Pertamax | E6: Rp | F6: Pertalite | G6: Rp | H6: Pertamax | I6: Rp | J6: Pertalite | K6: Rp | L6: solar | M6: Rp | N6: solar | O6: Rp | P6: pertamax | Q6: Rp | R6: Pertamina Dex | S6: Rp | T6: Solar | U6: Rp | V6: Liter | W6: Rp | X6: Liter | Y6: Rp | Z6: Liter | AA6: Rp | AB6: Liter | AC6: Rp
A7: 45901 | B7: 33.8 | C7: 338000 | F7: 25.33 | G7: 253300 | J7: 26.18 | K7: 261800 | V7: 20 | W7: 200000 | X7: 20 | Y7: 244000
V8: 10 | W8: 100000
A11: 45902 | B11: 34.68 | C11: 346800 | F11: 29.83 | G11: 298300 | L11: 20 | M11: 136000 | P11: 20 | Q11: 244000 | V11: 10 | W11: 100000 | X11: 20 | Y11: 244000
A15: 45903 | B15: 26.19 | C15: 261900 | F15: 27.96 | G15: 279600 | J15: 18.52 | K15: 185200 | T15: 20 | U15: 136000 | V15: 20 | W15: 200000
A19: 45904 | B19: 30.16 | C19: 301600 | F19: 25.78 | G19: 257800 | L19: 20 | M19: 136000 | N19: 35.53 | O19: 241604 | P19: 20 | Q19: 244000 | T19: 45.71 | U19: 310840 | X19: 20 | Y19: 244000
A23: 45905 | B23: 30.49 | C23: 304900 | F23: 27.26 | G23: 272600
A27: 45906 | F27: 27.44 | G27: 274400 | J27: 25.11 | K27: 251100 | V27: 10 | W27: 100000
X28: 20 | Y28: 244000
A31: 45907 | B31: 37.01 | C31: 370100 | F31: 29.73 | G31: 297300
A35: 45908 | B35: 31.42 | C35: 314200 | F35: 21.03 | G35: 210300 | J35: 23.61 | K35: 236100 | V35: 20 | W35: 200000
A39: 45909 | B39: 32.23 | C39: 322300 | F39: 32.39 | G39: 323900 | N39: 42.9 | O39: 291720 | P39: 20 | Q39: 244000 | X39: 20 | Y39: 244000
A43: 45910 | B43: 32.77 | C43: 327700 | F43: 27 | G43: 270000 | J43: 15.72 | K43: 157200 | L43: 20 | M43: 136000 | V43: 10 | W43: 100000 | X43: 20 | Y43: 244000 | Z43: 30.14 | AA43: 204952
A47: 45911 | B47: 33.12 | C47: 331200 | F47: 29.83 | G47: 298300
A51: 45912 | B51: 32.71 | C51: 327110 | F51: 23.93 | G51: 239300 | P51: 20 | Q51: 244000 | T51: 60 | U51: 408000
A55: 45913 | B55: 29.41 | C55: 294100 | F55: 25.45 | G55: 254500 | J55: 25.27 | K55: 252700 | P55: 20 | Q55: 244000
A59: 45914 | B59: 32.5 | C59: 325000 | F59: 24.05 | G59: 240500
A63: 45915 | B63: 18.51 | C63: 185100 | F63: 28.05 | G63: 280500 | J63: 19.66 | K63: 196600 | L63: 20 | M63: 136000 | V63: 10 | W63: 100000 | X63: 20 | Y63: 244000
A67: 45916 | B67: 34.2 | C67: 342000 | F67: 25.6 | G67: 256000 | N67: 55.87 | O67: 379916 | P67: 20 | Q67: 244000
A71: 45917 | B71: 33 | C71: 330000 | F71: 33.34 | G71: 333400 | T71: 60 | U71: 408000 | V71: 20 | W71: 200000 | X71: 20 | Y71: 244000
A75: 45918 | B75: 32.65 | C75: 326500 | F75: 27.63 | G75: 276300 | X75: 20 | Y75: 244000
A79: 45919 | B79: 33.57 | C79: 335700 | F79: 25.51 | G79: 255100 | J79: 21.32 | K79: 213200 | V79: 20 | W79: 200000
V80: 9.91 | W80: 99100
A83: 45920 | B83: 15.38 | C83: 153800 | F83: 29.83 | G83: 298300 | L83: 58.06 | M83: 394808 | X83: 20 | Y83: 244000
A87: 45921 | B87: 45.09 | C87: 450900 | F87: 30.04 | G87: 300400
A91: 45922 | B91: 28.06 | C91: 280600 | F91: 29.33 | G91: 293300
A95: 45923 | B95: 32.96 | C95: 329600 | F95: 33.73 | G95: 337300 | P95: 20 | Q95: 244000 | T95: 52.19 | U95: 354892 | X95: 20 | Y95: 244000
A99: 45924 | B99: 28.74 | C99: 287400 | F99: 29.36 | G99: 293600 | J99: 26.12 | K99: 261200 | V99: 20 | W99: 200000
A103: 45925 | B103: 29.8 | C103: 298000 | F103: 30.75 | G103: 307500 | V103: 10 | W103: 100000 | X103: 20 | Y103: 244000
A107: 45926 | B107: 28.57 | C107: 285700 | F107: 27.62 | G107: 276200 | J107: 27.27 | K107: 272700 | P107: 20 | Q107: 244000 | Z107: 35.85 | AA107: 243780
A111: 45927 | B111: 26.35 | C111: 263500 | D111: 20 | E111: 244000 | F111: 29.48 | G111: 294800 | J111: 21.68 | K111: 216800 | T111: 39.05 | U111: 265540
A115: 45928 | B115: 29.32 | C115: 293200 | F115: 28.16 | G115: 281600
A119: 45929 | B119: 30.47 | C119: 304700 | F119: 23.29 | G119: 232900 | J119: 26.03 | K119: 260300 | N119: 59.15 | O119: 402220 | X119: 20 | Y119: 244000
A123: 45930 | B123: 32.68 | C123: 326800 | F123: 30.8 | G123: 308000 | J123: 19.44 | K123: 194400 | N123: 60 | O123: 408000 | P123: 20 | Q123: 244000 | T123: 32.65 | U123: 222020 | X123: 20 | Y123: 244000
A127: TOTAL | C127: =SUM(C7:C126) -> 8958410 | E127: =SUM(E7:E126) -> 244000 | G127: =SUM(G7:G126) -> 8395300 | I127: =SUM(I7:I126) -> 0 | K127: =SUM(K7:K126) -> 2959300 | M127: =SUM(M7:M126) -> 938808 | O127: =SUM(O7:O126) -> 1723460 | Q127: =SUM(Q7:Q126) -> 2196000 | S127: =SUM(S7:S126) -> 0 | U127: =SUM(U7:U126) -> 2105292 | W127: =SUM(W7:W126) -> 1899100 | Y127: =SUM(Y7:Y126) -> 3416000 | AA127: =SUM(AA7:AA126) -> 448732 | AC127: =SUM(AC7:AC126) -> 0 | AD127: =SUM(B127:AC127) -> 33284402
...

Sheet AGUSTUS 2025
A1: LAPORAN KONSUMSI BBM KENDARAAN DINAS PT PELINDO DAYA SEJAHTERA
A2: PERIODE AGUSTUS 2025
A3: SUGENG | V3: MAS WAFI
A4: TANGGAL | B4: HANTARAN OPERATOR ITV TPS | L4: OPERASIONAL KEBERSHAN TPS | V4: SAPU JALAN PERAK BARAT | X4: PENYIRAMAN PERAK | Z4: SAPU JALAN (SPMT) | AB4: KEBERSIHAN PERAK | AD4: GRAND TOTAL
B5: L 1941 OL (L 1873 SB) | D5: L 1941 OL (L 1873 SB) | F5: L 1536 MZ (L 1388 PC) | H5: L 1536 MZ (L 1388 PC) | J5: L 1838 ZB (L 1641 PA) | L5: L 8203 AF | N5: L 9910 BR | P5: L 9910 BR | R5: L 9034 BU | T5: L 9078 BU | V5: pertalite | W5: L 9662 NK | X5: pertamax | Y5: L 9964 NK | Z5: Solar | AA5: AE 8719 SQ/L 8393 LT | AB5: pertalite | AC5: L 8065 TR
B6: Pertalite | C6: Rp | D6: Pertamax | E6: Rp | F6: Pertalite | G6: Rp | H6: Pertamax | I6: Rp | J6: Pertalite | K6: Rp | L6: solar | M6: Rp | N6: solar | O6: Rp | P6: pertamax | Q6: Rp | R6: Pertamina Dex | S6: Rp | T6: Solar | U6: Rp | V6: Liter | W6: Rp | X6: Liter | Y6: Rp | Z6: Liter | AA6: Rp | AB6: Liter | AC6: Rp
A7: 45870 | B7: 31.59 | C7: 315900 | F7: 21.48 | G7: 214800 | J7: 21.63 | K7: 216300 | V7: 20 | W7: 200000 | X7: 20 | Y7: 244000
A11: 45871 | B11: 24.58 | C11: 245800 | F11: 23.52 | G11: 235200 | P11: 20 | Q11: 244000 | T11: 57.95 | U11: 394060 | V11: 10 | W11: 100000
A15: 45872 | B15: 27.37 | C15: 273700 | F15: 27.16 | G15: 271600 | J15: 12.08 | K15: 120800 | L15: 20 | M15: 136000
A19: 45873 | B19: 30.23 | C19: 302300 | F19: 29.74 | G19: 297400 | N19: 60 | O19: 408000 | V19: 20 | W19: 200000 | X19: 20 | Y19: 244000
A23: 45874 | P23: 20 | Q23: 244000
B24: 31.65 | C24: 316500 | F24: 29.81 | G24: 298100
A27: 45875 | B27: 25.28 | C27: 252800 | F27: 26.43 | G27: 264300 | J27: 26.53 | K27: 265300 | X27: 20 | Y27: 244000
A31: 45876 | B31: 33.09 | C31: 330900 | F31: 25.32 | G31: 253200
A35: 45877 | B35: 31.35 | C35: 313500 | F35: 28.19 | G35: 281900 | J35: 14.05 | K35: 140500 | L35: 20 | M35: 136000 | V35: 10 | W35: 100000
A39: 45878 | B39: 30.32 | C39: 303200 | F39: 27.66 | G39: 276600 | P39: 20 | Q39: 244000 | T39: 56.3 | U39: 382840
A43: 45879 | B43: 39.26 | C43: 392600 | F43: 38.81 | G43: 388100
A47: 45880 | B47: 23.91 | C47: 239100 | F47: 14.05 | G47: 140500 | J47: 23.64 | K47: 236400 | V47: 20 | W47: 200000 | X47: 20 | Y47: 244000 | Z47: 33.66 | AA47: 228890
A51: 45881 | B51: 34 | C51: 340000 | F51: 29 | G51: 290000 | P51: 20 | Q51: 244000
A55: 45882 | B55: 29.94 | C55: 299400 | F55: 29.68 | G55: 296800 | J55: 18.51 | K55: 185100 | L55: 20 | M55: 136000 | N55: 60 | O55: 408000
A59: 45883 | B59: 29 | C59: 290000 | F59: 33.71 | G59: 337100 | T59: 60 | U59: 408000 | V59: 10 | W59: 100000 | X59: 20 | Y59: 244000
A63: 45884 | B63: 27.96 | C63: 279600 | F63: 26.26 | G63: 262600 | X63: 20 | Y63: 244000
A67: 45885 | B67: 32.83 | C67: 328300 | F67: 27.5 | G67: 275000 | J67: 23.28 | K67: 232800 | P67: 20 | Q67: 244000
A71: 45886 | B71: 29.88 | C71: 298800 | F71: 22.17 | G71: 221700
A75: 45887 | F75: 28.37 | G75: 283700 | L75: 57.89 | M75: 393650
V77: 20 | W77: 200000
A79: 45888 | B79: 29.85 | C79: 298500 | F79: 24.95 | G79: 249500 | J79: 19.74 | K79: 197400 | V79: 25 | W79: 250000 | X79: 20 | Y79: 244000
B80: 36.23 | C80: 362300
A83: 45889 | B83: 33.23 | C83: 332300 | F83: 29.55 | G83: 295500 | T83: 60 | U83: 408000 | V83: 10 | W83: 100000
A87: 45890 | B87: 29.65 | C87: 296500 | D87: 20 | E87: 244000 | F87: 29.45 | G87: 294500 | J87: 21.7 | K87: 217000
A91: 45891 | B91: 30.21 | C91: 302100 | F91: 32.92 | G91: 329200 | J91: 16.27 | K91: 162700 | N91: 60 | O91: 408000 | P91: 20 | Q91: 244000
A95: 45892 | B95: 29.88 | C95: 298800 | F95: 27.82 | G95: 278200 | X95: 20 | Y95: 244000
A99: 45893 | B99: 39.1 | C99: 391000 | F99: 29.58 | G99: 295800 | T99: 20 | U99: 136000
A103: 45894 | B103: 32.98 | C103: 329800 | F103: 21.62 | G103: 216200 | J103: 20.1 | K103: 201000 | V103: 20 | W103: 200000
A107: 45895 | V107: 10 | W107: 100000
B110: 29.61 | C110: 296100 | F110: 24.2 | G110: 242000 | N110: 55.68 | O110: 378624 | P110: 20 | Q110: 244000
A111: 45896
B114: 27.78 | C114: 277800 | F114: 30.88 | G114: 308800 | X114: 20 | Y114: 244000
A115: 45897 | Z115: 35.34 | AA115: 240312
B118: 32.44 | C118: 324400 | F118: 23.98 | G118: 239800 | J118: 29.23 | K118: 292300 | L118: 20 | M118: 136000
...

Sheet JULI 2025
A1: LAPORAN KONSUMSI BBM KENDARAAN DINAS PT PELINDO DAYA SEJAHTERA
A2: PERIODE JULI 2025
A3: SUGENG | V3: MAS WAFI
A4: TANGGAL | B4: HANTARAN OPERATOR ITV TPS | L4: OPERASIONAL KEBERSHAN TPS | V4: SAPU JALAN PERAK BARAT | X4: PENYIRAMAN PERAK | Z4: SAPU JALAN (SPMT) | AB4: KEBERSIHAN PERAK | AD4: GRAND TOTAL
B5: L 1941 OL (L 1873 SB) | D5: L 1941 OL (L 1873 SB) | F5: L 1536 MZ (L 1388 PC) | H5: L 1536 MZ (L 1388 PC) | J5: L 1838 ZB (L 1641 PA) | L5: L 8203 AF | N5: L 9910 BR | P5: L 9910 BR | R5: L 9034 BU | T5: L 9078 BU | V5: pertalite | W5: L 9662 NK | X5: pertamax | Y5: L 9964 NK | Z5: Solar | AA5: AE 8719 SQ/L 8393 LT | AB5: pertalite | AC5: L 8065 TR
B6: Pertalite | C6: Rp | D6: Pertamax | E6: Rp | F6: Pertalite | G6: Rp | H6: Pertamax | I6: Rp | J6: Pertalite | K6: Rp | L6: solar | M6: Rp | N6: solar | O6: Rp | P6: pertamax | Q6: Rp | R6: Pertamina Dex | S6: Rp | T6: Solar | U6: Rp | V6: Liter | W6: Rp | X6: Liter | Y6: Rp | Z6: Liter | AA6: Rp | AB6: Liter | AC6: Rp
A7: 45839 | B7: 28.14 | C7: 281400 | F7: 31.9 | G7: 319000 | J7: 23.48 | K7: 234800 | P7: 20 | Q7: 250000 | X7: 20 | Y7: 250000
A11: 45840 | B11: 30.22 | C11: 302200 | J11: 14.18 | K11: 141800 | V11: 20 | W11: 200000 | X11: 20 | Y11: 250000
A15: 45841 | B15: 30.41 | C15: 304100 | F15: 32.64 | G15: 326400 | J15: 16.71 | K15: 167100 | P15: 21.6 | Q15: 270000
A19: 45842 | B19: 27.63 | C19: 276300 | F19: 32.42 | G19: 324200 | J19: 13.3 | K19: 133000 | X19: 20 | Y19: 250000
A23: 45843 | B23: 27.49 | C23: 279900 | F23: 25.67 | G23: 256700 | J23: 12 | K23: 120000 | N23: 60 | O23: 408000 | P23: 20 | Q23: 250000 | X23: 20 | Y23: 250000
A27: 45844 | B27: 26.73 | C27: 267300 | F27: 27.89 | G27: 278900 | J27: 19.11 | K27: 191100
A31: 45845 | B31: 38.69 | C31: 386900 | F31: 28.26 | G31: 282600 | J31: 12.6 | K31: 126000 | T31: 60 | U31: 408000 | AB31: 20 | AC31: 200000
A35: 45846 | F35: 26.64 | G35: 266400 | J35: 25.91 | K35: 259100 | P35: 20 | Q35: 250000 | V35: 20 | W35: 200000 | X35: 20 | Y35: 250000
A39: 45847 | B39: 32.58 | C39: 325800 | F39: 27.3 | G39: 273000 | J39: 15.2 | K39: 152000 | L39: 20 | M39: 136000 | X39: 20 | Y39: 250000 | Z39: 36.76 | AA39: 250000
A43: 45848 | B43: 28.2 | C43: 282000
B44: 27.21 | C44: 272100
A47: 45849 | B47: 29.62 | C47: 296200 | F47: 26.52 | G47: 265200 | J47: 27.26 | K47: 272600 | N47: 60 | O47: 408000 | P47: 20 | Q47: 250000 | T47: 49.49 | U47: 336532
A51: 45850 | B51: 24.66 | C51: 246600 | F51: 26.2 | G51: 262000 | V51: 10 | W51: 100000 | X51: 20 | Y51: 250000
A55: 45851 | B55: 33.54 | C55: 335400 | F55: 29.78 | G55: 297800 | J55: 29.71 | K55: 297100 | L55: 20 | M55: 136000
A59: 45852 | B59: 28.05 | C59: 280500 | F59: 27.75 | G59: 277500 | J59: 17.6 | K59: 176000 | P59: 20 | Q59: 250000 | V59: 20 | W59: 200000 | X59: 20 | Y59: 250000
A63: 45853 | B63: 22.41 | C63: 224100 | F63: 27.21 | G63: 272100
A67: 45854 | B67: 31.77 | C67: 317700 | H67: 24.56 | I67: 245600 | J67: 24.97 | K67: 249700 | X67: 20 | Y67: 250000
A71: 45855 | B71: 18.76 | C71: 187600 | F71: 29.71 | G71: 297100 | J71: 34.62 | K71: 346200 | V71: 25 | W71: 250000
A75: 45856 | B75: 39.04 | C75: 390400 | F75: 26.88 | G75: 268800 | J75: 17.1 | K75: 171000 | L75: 20 | M75: 136000 | V75: 39.87 | W75: 398700 | X75: 20 | Y75: 250000
A79: 45857 | B79: 22 | C79: 220000 | F79: 28.63 | G79: 286300 | J79: 27.22 | K79: 272200 | V79: 9.1 | W79: 91000 | X79: 20 | Y79: 250000
A83: 45858 | B83: 19.55 | C83: 195500 | F83: 25.54 | G83: 255400 | J83: 24.05 | K83: 240500 | P83: 20 | Q83: 250000
A87: 45859 | B87: 27.38 | C87: 273800 | F87: 27.6 | G87: 276000 | J87: 19.51 | K87: 195100 | N87: 56.91 | O87: 386988 | P87: 20 | Q87: 250000 | T87: 60 | U87: 408000 | AB87: 20 | AC87: 200000
A91: 45860 | B91: 21.03 | C91: 210300 | F91: 28.04 | G91: 280400 | J91: 22.02 | K91: 220200 | X91: 20 | Y91: 250000
A95: 45861 | B95: 22.9 | C95: 229000 | F95: 23.61 | G95: 236100 | J95: 25.99 | K95: 259900 | L95: 20 | M95: 136000 | X95: 20 | Y95: 250000
A99: 45862 | B99: 31.38 | C99: 313800 | F99: 27.21 | G99: 272100 | Z99: 32.71 | AA99: 222428
A103: 45863 | B103: 18.14 | C103: 181400 | F103: 23.46 | G103: 234600 | J103: 34.02 | K103: 340200 | P103: 20 | Q103: 250000 | X103: 20 | Y103: 250000
A107: 45864 | B107: 22.95 | C107: 229500 | F107: 28.3 | G107: 283000 | J107: 19.67 | K107: 196700 | AB107: 9 | AC107: 90000
A111: 45865 | B111: 22.77 | C111: 227700 | F111: 29.97 | G111: 299700 | J111: 16.61 | K111: 166100
F112: 27.88 | G112: 278800
A115: 45866 | B115: 29.18 | C115: 291800 | F115: 30.82 | G115: 308200 | L115: 20 | M115: 136000 | P115: 20 | Q115: 250000 | T115: 58.25 | U115: 396100 | X115: 20 | Y115: 250000
A119: 45867 | B119: 24.71 | C119: 247100 | X119: 20 | Y119: 250000 | AB119: 20 | AC119: 200000
A123: 45868 | B123: 21.98 | C123: 219800 | F123: 23.69 | G123: 236900 | J123: 14.35 | K123: 143500 | N123: 58.52 | O123: 397940 | X123: 20 | Y123: 250000
A127: 45869 | B127: 25.41 | C127: 254100 | F127: 24.61 | G127: 246100
A131: TOTAL | C131: =SUM(C7:C130) -> 8350300 | E131: =SUM(E7:E130) -> 0 | G131: =SUM(G7:G130) -> 7761300 | I131: =SUM(I7:I130) -> 245600 | K131: =SUM(K7:K130) -> 5071900 | M131: =SUM(M7:M130) -> 680000 | O131: =SUM(O7:O130) -> 1600928 | Q131: =SUM(Q7:Q130) -> 2520000 | S131: =SUM(S7:S130) -> 0 | U131: =SUM(U7:U130) -> 1548632 | W131: =SUM(W7:W130) -> 1439700 | Y131: =SUM(Y7:Y130) -> 4250000 | AA131: =SUM(AA7:AA130) -> 472428 | AC131: =SUM(AC7:AC130) -> 690000 | AD131: =SUM(B131:AC131) -> 34630788
...

Sheet JUNI 2025
A1: LAPORAN KONSUMSI BBM KENDARAAN DINAS PT PELINDO DAYA SEJAHTERA
A2: PERIODE JUNI 2025
A3: SUGENG | V3: MAS WAFI
A4: TANGGAL | B4: HANTARAN OPERATOR ITV TPS | L4: OPERASIONAL KEBERSHAN TPS | V4: SAPU JALAN PERAK BARAT | X4: PENYIRAMAN PERAK | Z4: SAPU JALAN (SPMT) | AB4: KEBERSIHAN PERAK | AD4: GRAND TOTAL
B5: L 1941 OL (L 1873 SB) | D5: L 1941 OL (L 1873 SB) | F5: L 1536 MZ (L 1388 PC) | H5: L 1536 MZ (L 1388 PC) | J5: L 1838 ZB (L 1641 PA) | L5: L 8203 AF | N5: L 9910 BR | P5: L 9910 BR | R5: L 9034 BU | T5: L 9078 BU | V5: pertalite | W5: L 9662 NK | X5: pertamax | Y5: L 9964 NK | Z5: Solar | AA5: AE 8719 SQ/L 8393 LT | AB5: pertalite | AC5: L 8065 TR
B6: Pertalite | C6: Rp | D6: Pertamax | E6: Rp | F6: Pertalite | G6: Rp | H6: Pertamax | I6: Rp | J6: Pertalite | K6: Rp | L6: solar | M6: Rp | N6: solar | O6: Rp | P6: pertamax | Q6: Rp | R6: Pertamina Dex | S6: Rp | T6: Solar | U6: Rp | V6: Liter | W6: Rp | X6: Liter | Y6: Rp | Z6: Liter | AA6: Rp | AB6: Liter | AC6: Rp
A7: 45809 | B7: 33.3 | C7: 333000 | F7: 29.59 | G7: 295900 | J7: 24.54 | K7: 245400 | T7: 60 | U7: 408000
A11: 45810 | B11: 31.38 | C11: 313800 | F11: 27.17 | G11: 271700 | J11: 18.16 | K11: 181600 | L11: 20 | M11: 136000 | P11: 20 | Q11: 242000 | AB11: 25 | AC11: 250000
A15: 45811 | B15: 38.96 | C15: 389600 | F15: 27 | G15: 270000 | J15: 22.42 | K15: 224200 | X15: 20 | Y15: 242000
A19: 45812 | B19: 28.54 | C19: 285400 | F19: 29.53 | G19: 295300 | J19: 18.25 | K19: 182500 | N19: 20 | O19: 136000 | X19: 20 | Y19: 242000
A23: 45813 | B23: 30.08 | C23: 300800 | F23: 29.69 | G23: 296900 | J23: 24.86 | K23: 248600 | P23: 20 | Q23: 242000
A27: 45814 | B27: 27.91 | C27: 279100 | F27: 25.13 | G27: 251300 | J27: 19.64 | K27: 196400 | N27: 50.96 | O27: 346530 | P27: 20 | Q27: 242000
A31: 45815 | B31: 25.34 | C31: 253400 | F31: 21.89 | G31: 218900 | AB31: 20 | AC31: 200000
A35: 45816 | B35: 29.69 | C35: 296900 | F35: 30.15 | G35: 301500 | J35: 21.9 | K35: 219000
A39: 45817 | B39: 30.37 | C39: 303700 | F39: 28.86 | G39: 288600 | L39: 20 | M39: 136000 | X39: 20 | Y39: 242000
A43: 45818 | B43: 29.58 | C43: 295800 | F43: 29.62 | G43: 296200 | J43: 25.95 | K43: 259500 | P43: 20 | Q43: 242000 | T43: 20 | U43: 136000
A47: 45819 | B47: 35.01 | C47: 350100 | F47: 27.35 | G47: 273500 | J47: 19.78 | K47: 197800 | AB47: 20 | AC47: 200000
A51: 45820 | B51: 34.23 | C51: 342300 | F51: 22.47 | G51: 224700 | J51: 19.82 | K51: 198200 | N51: 60 | O51: 408000 | P51: 20 | Q51: 242000 | X51: 20 | Y51: 242000
A55: 45821 | B55: 34.41 | C55: 344100 | F55: 28.16 | G55: 281600 | J55: 21.34 | K55: 213400 | L55: 20 | M55: 136000 | AB55: 20 | AC55: 200000
A59: 45822 | B59: 29.8 | C59: 298000 | H59: 16.32 | I59: 200000 | X59: 20 | Y59: 242000
A63: 45823 | B63: 29.42 | C63: 294200 | F63: 39.99 | G63: 399900 | J63: 24.92 | K63: 249200
A67: 45824 | B67: 29.84 | C67: 298400 | F67: 36.99 | G67: 369900 | J67: 20.6 | K67: 206000 | N67: 20 | O67: 242000 | T67: 60 | U67: 408000 | AB67: 20 | AC67: 200000
A71: 45825 | B71: 30.33 | C71: 303300 | F71: 31.19 | G71: 311900
A75: 45826 | B75: 29.73 | C75: 297300 | F75: 29.5 | G75: 295000 | J75: 33.12 | K75: 331200 | L75: 20 | M75: 136000
B76: 33.53 | C76: 335300
A79: 45827 | B79: 29.88 | C79: 298800 | F79: 29.45 | G79: 294500 | J79: 17.11 | K79: 171100 | X79: 20 | Y79: 242000 | AB79: 20 | AC79: 200000
A83: 45828 | B83: 26.57 | C83: 265700 | F83: 29.99 | G83: 299900 | J83: 10.9 | K83: 109000 | X83: 20 | Y83: 242000 | Z83: 32.87 | AA83: 223516
A87: 45829 | B87: 35.64 | C87: 356400 | F87: 25.06 | G87: 250600 | J87: 26.01 | K87: 260100 | N87: 60 | O87: 408000
A91: 45830 | B91: 35.83 | C91: 358300 | F91: 33.03 | G91: 330300
A95: 45831 | B95: 29.85 | C95: 298500 | F95: 12.42 | G95: 124200 | J95: 25.01 | K95: 250100 | L95: 20 | M95: 136000 | P95: 20 | Q95: 242000 | X95: 20 | Y95: 242000 | AB95: 19.62 | AC95: 196200
A99: 45832 | B99: 27.83 | C99: 278300 | F99: 35.1 | G99: 351000 | J99: 15.68 | K99: 156800 | X99: 20 | Y99: 242000
A103: 45833 | F103: 28.3 | G103: 283000 | J103: 21.38 | K103: 213800 | X103: 20 | Y103: 242000 | AB103: 20 | AC103: 200000
A107: 45834 | F107: 25.92 | G107: 259200 | J107: 29.53 | K107: 295300 | N107: 60 | O107: 408000 | T107: 60 | U107: 408000
A111: 45835 | B111: 35.38 | C111: 353800 | F111: 32.19 | G111: 321900 | J111: 25.33 | K111: 253300
A115: 45836 | B115: 35.94 | C115: 359400 | F115: 27.12 | G115: 271200
A119: 45837 | B119: 23.58 | C119: 235800 | H119: 29.76 | I119: 297600 | J119: 32.13 | K119: 321300 | L119: 20 | M119: 136000
A123: 45838 | B123: 13.02 | C123: 390200 | F123: 25.28 | G123: 252800 | X123: 20 | Y123: 242000 | AB123: 20 | AC123: 200000
A127: TOTAL | C127: =SUM(C7:C126) -> 9109700 | E127: =SUM(E7:E126) -> 0 | G127: =SUM(G7:G126) -> 7981400 | I127: =SUM(I7:I126) -> 497600 | K127: =SUM(K7:K126) -> 5183800 | M127: =SUM(M7:M126) -> 816000 | O127: =SUM(O7:O126) -> 1948530 | Q127: =SUM(Q7:Q126) -> 1452000 | S127: =SUM(S7:S126) -> 0 | U127: =SUM(U7:U126) -> 1360000 | W127: =SUM(W7:W126) -> 0 | Y127: =SUM(Y7:Y126) -> 2662000 | AA127: =SUM(AA7:AA126) -> 223516 | AC127: =SUM(AC7:AC126) -> 1846200 | AD127: =SUM(B127:AC127) -> 33080746
B128: =SUM(B7:B126) -> 884.97 | D128: =SUM(D7:D126) -> 0 | F128: =SUM(F7:F127) -> 798.14 | H128: =SUM(H7:H126) -> 46.08 | J128: =SUM(J7:J127) -> 518.38 | L128: =SUM(L7:L127) -> 120 | N128: =SUM(N7:N127) -> 270.96 | P128: =SUM(P7:P127) -> 120 | R128: =SUM(R7:R127) -> 0 | T128: =SUM(T7:T127) -> 200 | V128: =SUM(V7:V127) -> 0 | X128: =SUM(X7:X127) -> 220 | Z128: =SUM(Z7:Z127) -> 32.87 | AB128: =SUM(AB6:AB127) -> 184.62 | AD128: =SUM(B128:AC128) -> 3396.02
A132: LAPORAN KONSUMSI BBM KENDARAAN DINAS PT PELINDO DAYA SEJAHTERA PERIODE JUNI 2025
...

Sheet MEI 2025
A1: LAPORAN KONSUMSI BBM KENDARAAN DINAS PT PELINDO DAYA SEJAHTERA
A2: PERIODE MEI 2025
A3: SUGENG | V3: MAS WAFI
A4: TANGGAL | B4: HANTARAN OPERATOR ITV TPS | L4: OPERASIONAL KEBERSHAN TPS | V4: SAPU JALAN PERAK BARAT | X4: PENYIRAMAN PERAK | Z4: SAPU JALAN (SPMT) | AB4: KEBERSIHAN PERAK | AD4: GRAND TOTAL
B5: L 1941 OL (L 1873 SB) | D5: L 1941 OL (L 1873 SB) | F5: L 1536 MZ (L 1388 PC) | H5: L 1536 MZ (L 1388 PC) | J5: L 1838 ZB (L 1641 PA) | L5: L 8203 AF | N5: L 9910 BR | P5: L 9910 BR | R5: L 9034 BU | T5: L 9078 BU | V5: pertalite | W5: L 9662 NK | X5: pertamax | Y5: L 9664 NK | Z5: Solar | AA5: AE 8719 SQ/L 8393 LT | AB5: pertalite | AC5: L 8065 TR
B6: Pertalite | C6: Rp | D6: Pertamax | E6: Rp | F6: Pertalite | G6: Rp | H6: Pertamax | I6: Rp | J6: Pertalite | K6: Rp | L6: solar | M6: Rp | N6: solar | O6: Rp | P6: pertamax | Q6: Rp | R6: Pertamina Dex | S6: Rp | T6: Solar | U6: Rp | V6: Liter | W6: Rp | X6: Liter | Y6: Rp | Z6: Liter | AA6: Rp | AB6: Liter | AC6: Rp
A7: 45778
B8: 31.46 | C8: 314600 | F8: 32.28 | G8: 322800
A11: 45779 | B11: 27.51 | C11: 275100 | F11: 21.73 | G11: 217300
A15: 45780 | B15: 30.03 | C15: 300300 | F15: 31.73 | G15: 317300 | X15: 20.16 | Y15: 250000 | AB15: 20 | AC15: 200000
AB16: 20 | AC16: 200000
A19: 45781 | B19: 33.42 | C19: 334270 | F19: 29.98 | G19: 299800 | J19: 32.33 | K19: 323300
A23: 45782 | B23: 38.35 | C23: 383500 | F23: 26.53 | G23: 265300 | J23: 18.72 | K23: 187200 | L23: 20 | M23: 136000
A27: 45783 | B27: 31.14 | C27: 311400 | F27: 29.09 | G27: 290900 | J27: 19.62 | K27: 196200 | P27: 20 | Q27: 248000 | X27: 20 | Y27: 248000
A31: 45784 | B31: 33.34 | C31: 333400 | F31: 28.1 | G31: 281000 | J31: 25.26 | K31: 252600 | T31: 60 | U31: 408000
A35: 45785 | B35: 29.53 | C35: 295300 | F35: 29.74 | G35: 297400 | J35: 16.75 | K35: 167500 | L35: 20 | M35: 136000 | N35: 20 | O35: 136000 | P35: 20 | Q35: 248000 | X35: 20 | Y35: 248000 | AB35: 20 | AC35: 200000
AB36: 20 | AC36: 200000
A39: 45786 | B39: 25.15 | C39: 251500 | F39: 27.92 | G39: 279200 | J39: 20.26 | K39: 202600 | X39: 20 | Y39: 248000 | Z39: 42.29 | AA39: 287572
A43: 45787 | B43: 29.56 | C43: 295600 | F43: 26.79 | G43: 267900 | J43: 18.68 | K43: 186800 | N43: 53.39 | O43: 363052
A47: 45788 | B47: 36.41 | C47: 364100 | F47: 33.64 | G47: 336400
A51: 45789 | B51: 29.64 | C51: 296400 | F51: 27.37 | G51: 273700 | J51: 31.57 | K51: 315700
A55: 45790 | B55: 34.24 | C55: 342400 | F55: 23.07 | G55: 230700 | J55: 14.24 | K55: 142400 | AB55: 20 | AC55: 200000
A59: 45791 | B59: 24.99 | C59: 249900 | F59: 29.14 | G59: 291400 | P59: 20 | Q59: 248000
A63: 45792 | B63: 36.72 | C63: 367200 | F63: 25.35 | G63: 253500 | J63: 38.27 | K63: 382700
A67: 45793 | B67: 29.25 | C67: 292500 | F67: 29.87 | G67: 298700 | J67: 23.53 | K67: 235300 | L67: 20 | M67: 136000 | N67: 20 | O67: 136000 | P67: 20 | Q67: 248000 | X67: 20 | Y67: 248000
A71: 45794 | B71: 29.85 | C71: 298500 | F71: 32.89 | G71: 328900 | J71: 21.01 | K71: 210100 | N71: 46.79 | O71: 318172
A75: 45795 | B75: 31.67 | C75: 316700 | F75: 27.51 | G75: 275100 | J75: 23.22 | K75: 232200
A79: 45796 | B79: 32.93 | C79: 329300 | F79: 30 | G79: 300000 | AB79: 20 | AC79: 200000
AB80: 20 | AC80: 200000
A83: 45797 | B83: 25.27 | C83: 252700 | F83: 23.11 | G83: 231100 | J83: 26.68 | K83: 266800 | P83: 20 | Q83: 248000
A87: 45798 | B87: 29.9 | C87: 299000 | F87: 22.6 | G87: 226000 | J87: 16.77 | K87: 167700 | X87: 20 | Y87: 248000
A91: 45799 | B91: 29.17 | C91: 291700 | F91: 26.85 | G91: 268500 | J91: 18.66 | K91: 186600 | L91: 20 | M91: 136000 | N91: 20 | O91: 136000 | T91: 60 | U91: 408000 | X91: 20 | Y91: 248000 | AB91: 20 | AC91: 200000
A95: 45800 | B95: 27.5 | C95: 275000 | F95: 33.35 | G95: 333500 | J95: 16.64 | K95: 166400 | P95: 20 | Q95: 248000 | X95: 20 | Y95: 248000
A99: 45801 | F99: 26.29 | G99: 262900 | J99: 16.35 | K99: 163500 | N99: 50.68 | O99: 344620
A103: 45802 | B103: 38.81 | C103: 388100 | F103: 32.89 | G103: 328900 | J103: 30.17 | K103: 301700
A107: 45803 | B107: 32.07 | C107: 320700 | F107: 32.22 | G107: 322200 | J107: 19.27 | K107: 192700 | P107: 20 | Q107: 248000 | AB107: 20 | AC107: 200000
A111: 45804 | B111: 27.72 | C111: 277200 | F111: 22.74 | G111: 227400 | J111: 28.37 | K111: 283700 | L111: 20 | M111: 136000 | X111: 20 | Y111: 248000
A115: 45805 | B115: 32.76 | C115: 327600 | F115: 28.32 | G115: 283200 | J115: 13.58 | K115: 135800
A119: 45806 | B119: 31.89 | C119: 318900 | F119: 30.45 | G119: 304500 | J119: 20.53 | K119: 205300 | N119: 52.43 | O119: 356524
A123: 45807 | B123: 30.36 | C123: 303600 | F123: 27.9 | G123: 279000 | Z123: 41.05 | AA123: 279140
...

Sheet APRIL 2025
A1: LAPORAN KONSUMSI BBM KENDARAAN DINAS PT PELINDO DAYA SEJAHTERA
A2: PERIODE APRIL 2025
A3: SUGENG | V3: MAS WAFI
A4: TANGGAL | B4: HANTARAN OPERATOR ITV TPS | L4: OPERASIONAL KEBERSHAN TPS | V4: SAPU JALAN PERAK BARAT | X4: PENYIRAMAN PERAK | Z4: SAPU JALAN (SPMT) | AB4: KEBERSIHAN PERAK | AD4: GRAND TOTAL
B5: L 1941 OL (L 1873 SB) | D5: L 1941 OL (L 1873 SB) | F5: L 1536 MZ (L 1388 PC) | H5: L 1536 MZ (L 1388 PC) | J5: L 1838 ZB (L 1641 PA) | L5: L 8203 AF | N5: L 9910 BR | P5: L 9910 BR | R5: L 9034 BU | T5: L 9078 BU | V5: pertalite | W5: L 9662 NK | X5: pertamax | Y5: L 9664 NK | Z5: Solar | AA5: AE 8719 SQ/L 8393 LT | AB5: pertalite | AC5: L 8065 TR
B6: Pertalite | C6: Rp | D6: Pertamax | E6: Rp | F6: Pertalite | G6: Rp | H6: Pertamax | I6: Rp | J6: Pertalite | K6: Rp | L6: solar | M6: Rp | N6: solar | O6: Rp | P6: pertamax | Q6: Rp | R6: Pertamina Dex | S6: Rp | T6: Solar | U6: Rp | V6: Liter | W6: Rp | X6: Liter | Y6: Rp | Z6: Liter | AA6: Rp | AB6: Liter | AC6: Rp
A7: 45748 | B7: 34.92 | C7: 349200 | F7: 20.56 | G7: 205600 | J7: 26.2 | K7: 262000
A11: 45749 | B11: 26.07 | C11: 260700 | J11: 23.26 | K11: 232600 | L11: 20 | M11: 136000
A15: 45750 | B15: 24.67 | C15: 246700 | F15: 35.44 | G15: 354400 | J15: 28.73 | K15: 287300 | AB15: 10 | AC15: 100000
A19: 45751 | B19: 27.52 | C19: 275200 | J19: 19.45 | K19: 194500
A23: 45752 | B23: 26.43 | C23: 264300 | F23: 31.83 | G23: 318300 | J23: 28.01 | K23: 280100
A27: 45753 | B27: 29.81 | C27: 298100 | F27: 17.98 | G27: 179800 | J27: 38.82 | K27: 388200 | L27: 20 | M27: 136000 | N27: 45.29 | O27: 308000
A31: 45754 | F31: 33.21 | G31: 332100 | J31: 26.39 | K31: 263900 | AB31: 20 | AC31: 200000
A35: 45755 | B35: 34.73 | C35: 347300 | F35: 19.11 | G35: 191100 | J35: 25.65 | K35: 256500 | P35: 20 | Q35: 250000 | T35: 60 | U35: 408000
A39: 45756 | B39: 23.31 | C39: 233100 | J39: 21.86 | K39: 218600 | L39: 20 | M39: 136000 | N39: 14.7 | O39: 100000 | V39: 10 | W39: 100000 | X39: 20 | Y39: 250000
AB40: 15 | AC40: 150000
A43: 45757 | B43: 30.46 | C43: 304600 | F43: 19.89 | G43: 198900 | J43: 25.73 | K43: 257300 | P43: 20 | Q43: 250000
A47: 45758 | B47: 26.73 | C47: 267300 | F47: 28.28 | G47: 282800 | J47: 23.27 | K47: 232700 | P47: 20 | Q47: 250000
A51: 45759 | B51: 26.43 | C51: 264300 | F51: 23.18 | G51: 231800 | J51: 20.76 | K51: 207600 | L51: 20 | M51: 136000
A55: 45760 | B55: 30 | C55: 300000 | F55: 29.75 | G55: 297500
A59: 45761 | B59: 33.14 | C59: 331400 | F59: 25.87 | G59: 258700 | J59: 32 | K59: 320000 | X59: 20 | Y59: 250000 | AB59: 20 | AC59: 200000
A63: 45762 | B63: 40.65 | C63: 406500 | D63: 12 | E63: 150000 | H63: 16 | I63: 200000 | L63: 20 | M63: 136000 | N63: 20 | O63: 136000 | P63: 20 | Q63: 250000 | AB63: 10 | AC63: 100000
D64: 12 | E64: 150000
A67: 45763 | F67: 38.95 | G67: 389500 | J67: 34.43 | K67: 344300 | X67: 20 | Y67: 250000
A71: 45764 | B71: 37.48 | C71: 374800 | F71: 14.99 | G71: 149900 | J71: 31.35 | K71: 313500 | P71: 20 | Q71: 250000 | T71: 60 | U71: 408000
A75: 45765 | B75: 32.27 | C75: 322700 | F75: 26.12 | G75: 261200 | J75: 16.3 | K75: 163000 | L75: 20 | M75: 136000 | N75: 60 | O75: 408000
A79: 45766 | B79: 30.24 | C79: 302400 | F79: 21.06 | G79: 210600 | J79: 18.55 | K79: 185500 | P79: 20 | Q79: 250000
A83: 45767 | B83: 33.27 | C83: 332700 | F83: 23.13 | G83: 231300 | J83: 17.31 | K83: 173100 | L83: 20 | M83: 136000
A87: 45768 | B87: 25.52 | C87: 255200 | F87: 28.52 | G87: 285200 | J87: 19.05 | K87: 190500 | P87: 20 | Q87: 250000 | X87: 20 | Y87: 250000 | Z87: 30.75 | AA87: 209100 | AB87: 20 | AC87: 200000
A91: 45769 | B91: 33.18 | C91: 331800 | F91: 25.82 | G91: 258200 | J91: 15.73 | K91: 157300
A95: 45770 | B95: 34.87 | C95: 348700 | J95: 27.1 | K95: 271000 | L95: 52.49 | M95: 356932 | N95: 20 | O95: 136000 | X95: 20 | Y95: 250000 | AB95: 25 | AC95: 250000
A99: 45771 | B99: 26.88 | C99: 268800 | F99: 38.86 | G99: 388600 | J99: 26.08 | K99: 260800 | L99: 20 | M99: 136000 | X99: 20 | Y99: 250000
A103: 45772 | B103: 24.35 | C103: 243500 | F103: 32.95 | G103: 329500 | J103: 23.67 | K103: 236700 | P103: 20 | Q103: 250000
A107: 45773 | B107: 28.9 | C107: 289000 | F107: 25.85 | G107: 258500 | J107: 15.69 | K107: 156900 | T107: 60 | U107: 408000
A111: 45774 | B111: 30.74 | C111: 307400 | F111: 29.27 | G111: 292700 | J111: 22.97 | K111: 229700
A115: 45775 | B115: 34.86 | C115: 348600 | F115: 30.97 | G115: 309700 | J115: 18.96 | K115: 189600 | T115: 56.97 | U115: 387460 | X115: 20 | Y115: 250000 | AB115: 20 | AC115: 200000
A119: 45776 | B119: 37.87 | C119: 378700 | F119: 30.08 | G119: 300800 | J119: 14.2 | K119: 142000 | L119: 20 | M119: 136000 | P119: 20 | Q119: 250000
A123: 45777 | B123: 28.24 | C123: 282400 | F123: 28 | G123: 280000 | J123: 15 | K123: 150000 | X123: 20 | Y123: 250000
A127: TOTAL | C127: =SUM(C7:C126) -> 8535400 | E127: =SUM(E7:E126) -> 300000 | G127: =SUM(G7:G126) -> 6796700 | I127: =SUM(I7:I126) -> 200000 | K127: =SUM(K7:K126) -> 6565200 | M127: =SUM(M7:M126) -> 1580932 | O127: =SUM(O7:O126) -> 1088000 | Q127: =SUM(Q7:Q126) -> 2250000 | S127: =SUM(S7:S126) -> 0 | U127: =SUM(U7:U126) -> 1611460 | W127: =SUM(W7:W126) -> 100000 | Y127: =SUM(Y7:Y126) -> 2000000 | AA127: =SUM(AA7:AA126) -> 209100 | AC127: =SUM(AC7:AC126) -> 1400000 | AD127: =SUM(B127:AC127) -> 32636792
B128: =SUM(B7:B126) -> 853.54 | D128: =SUM(D7:D126) -> 24 | F128: =SUM(F7:F127) -> 679.67 | H128: =SUM(H7:H126) -> 16 | J128: =SUM(J7:J127) -> 656.52 | L128: =SUM(L7:L127) -> 232.49 | N128: =SUM(N7:N127) -> 159.99 | P128: =SUM(P7:P127) -> 180 | R128: =SUM(R7:R127) -> 0 | T128: =SUM(T7:T127) -> 236.97 | V128: =SUM(V7:V127) -> 10 | X128: =SUM(X7:X127) -> 160 | Z128: =SUM(Z7:Z127) -> 30.75 | AB128: =SUM(AB6:AB127) -> 140 | AD128: =SUM(B128:AC128) -> 3379.93
...

Sheet MARET 2025
A1: LAPORAN KONSUMSI BBM KENDARAAN DINAS PT PELINDO DAYA SEJAHTERA
A2: PERIODE MARET 2025
A3: SUGENG | V3: MAS WAFI
A4: TANGGAL | B4: HANTARAN OPERATOR ITV TPS | L4: OPERASIONAL KEBERSHAN TPS | V4: SAPU JALAN PERAK BARAT | X4: PENYIRAMAN PERAK | Z4: SAPU JALAN (SPMT) | AB4: KEBERSIHAN PERAK | AD4: GRAND TOTAL
B5: L 1941 OL (L 1873 SB) | D5: L 1941 OL (L 1873 SB) | F5: L 1536 MZ (L 1388 PC) | H5: L 1536 MZ (L 1388 PC) | J5: L 1838 ZB (L 1641 PA) | L5: L 8203 AF | N5: L 9910 BR | P5: L 9910 BR | R5: L 9034 BU | T5: L 9078 BU | V5: pertalite | W5: L 9662 NK | X5: pertamax | Y5: L 9664 NK | Z5: Solar | AA5: AE 8719 SQ/L 8393 LT | AB5: pertalite | AC5: L 8065 TR
B6: Pertalite | C6: Rp | D6: Pertamax | E6: Rp | F6: Pertalite | G6: Rp | H6: Pertamax Turbo | I6: Rp | J6: Pertalite | K6: Rp | L6: solar | M6: Rp | N6: solar | O6: Rp | P6: pertamax | Q6: Rp | R6: Pertamina Dex | S6: Rp | T6: Solar | U6: Rp | V6: Liter | W6: Rp | X6: Liter | Y6: Rp | Z6: Liter | AA6: Rp | AB6: Liter | AC6: Rp
A7: 45717
B8: 28.05 | C8: 280500 | F8: 37.94 | G8: 379400 | N8: 37.22 | O8: 253096
A11: 45718 | B11: 38.83 | C11: 388300 | F11: 18.57 | G11: 185700 | J11: 37.74 | K11: 377400
A15: 45719 | B15: 30.87 | C15: 308700 | F15: 19.84 | G15: 198400 | J15: 23.42 | K15: 234200 | L15: 20 | M15: 136000 | T15: 20 | U15: 136000 | X15: 20 | Y15: 258000
A19: 45720 | B19: 27.13 | C19: 271300 | F19: 27.13 | G19: 271300 | J19: 20.93 | K19: 209300 | P19: 20 | Q19: 258000 | AB19: 10 | AC19: 100000
A23: 45721 | B23: 31.02 | C23: 310200 | F23: 22.35 | G23: 223500 | J23: 23.22 | K23: 232200 | X23: 20 | Y23: 258000
A27: 45722 | B27: 36.03 | C27: 360300 | F27: 25.5 | G27: 255000 | J27: 22.26 | K27: 222600 | L27: 20 | M27: 136000 | AB27: 10 | AC27: 100000
A31: 45723 | B31: 26.01 | C31: 260100 | F31: 18.82 | G31: 188200 | N31: 20 | O31: 136000 | P31: 20 | Q31: 258000 | T31: 58.8 | U31: 399840
A35: 45724 | B35: 28.95 | C35: 289500 | F35: 25.15 | G35: 251500 | J35: 26.89 | K35: 268900 | X35: 20 | Y35: 258000
A39: 45725 | B39: 29.81 | C39: 298100 | F39: 25.46 | G39: 254600 | J39: 25.13 | K39: 251300
A43: 45726 | B43: 27.26 | C43: 272600 | F43: 16.97 | G43: 169700 | L43: 20 | M43: 136000 | N43: 20 | O43: 136000 | AB43: 10 | AC43: 100000
A47: 45727 | B47: 26.79 | C47: 267900 | F47: 19.82 | G47: 198200 | J47: 39.63 | K47: 396300 | P47: 20 | Q47: 258000
A51: 45728 | B51: 27.46 | C51: 274600 | F51: 23.69 | G51: 236900 | J51: 21.45 | K51: 214500 | L51: 20 | M51: 136000 | X51: 20 | Y51: 258000
A55: 45729 | B55: 34.92 | C55: 349200 | F55: 20.82 | G55: 208200 | J55: 17.09 | K55: 170900 | Z55: 38.84 | AA55: 264112 | AB55: 20 | AC55: 200000
A59: 45730 | B59: 24.36 | C59: 243600 | F59: 27.5 | G59: 275000 | J59: 22.38 | K59: 223800 | N59: 20 | O59: 136000 | P59: 20 | Q59: 258000
A63: 45731 | B63: 22.91 | C63: 229100 | F63: 18.98 | G63: 189800 | J63: 24.82 | K63: 248200 | N63: 47.19 | O63: 320892 | X63: 20 | Y63: 258000
A67: 45732 | B67: 27.8 | C67: 278000 | F67: 25.34 | G67: 253400 | J67: 11.33 | K67: 113300 | L67: 20 | M67: 136000
A71: 45733 | B71: 28.46 | C71: 284600 | F71: 25.93 | G71: 259300 | J71: 19.54 | K71: 195400 | AB71: 10 | AC71: 100000
A75: 45734 | B75: 28.5 | C75: 285000 | F75: 21.28 | G75: 212800 | N75: 20 | O75: 136000 | P75: 20 | Q75: 258000
A79: 45735 | B79: 28.37 | C79: 283700 | F79: 20.96 | G79: 209600 | J79: 32.86 | K79: 328600 | L79: 20 | M79: 136000 | X79: 20 | Y79: 258000
A83: 45736 | B83: 27.31 | C83: 273100 | F83: 31.66 | G83: 316600 | J83: 17 | K83: 170000 | AB83: 20 | AC83: 200000
A87: 45737 | F87: 32.28 | G87: 322800 | J87: 25.71 | K87: 257100 | N87: 20 | O87: 136000 | P87: 20 | Q87: 258000
A91: 45738 | F91: 29.66 | G91: 296600 | J91: 33.82 | K91: 338200 | L91: 20 | M91: 136000 | N91: 50.72 | O91: 344896
A95: 45739 | F95: 28.94 | G95: 289400 | J95: 20.46 | K95: 204600
A99: 45740 | F99: 27.29 | G99: 272900 | J99: 29.45 | K99: 294500 | P99: 20 | Q99: 258000 | T99: 20 | U99: 136000 | AB99: 10 | AC99: 100000
A103: 45741 | F103: 30.35 | G103: 303500 | J103: 31.41 | K103: 314100 | L103: 20 | M103: 136000 | X103: 20 | Y103: 258000 | AB103: 20 | AC103: 200000
A107: 45742 | B107: 37.5 | C107: 375000 | J107: 19.06 | K107: 190600
F108: 25.31 | G108: 253100
A111: 45743 | B111: 29.92 | C111: 299200 | F111: 26.55 | G111: 265500 | J111: 25.19 | K111: 251900 | P111: 20 | Q111: 258000 | T111: 20 | U111: 136000
A115: 45744 | B115: 22.2 | C115: 222000 | F115: 26.75 | G115: 267500 | J115: 26.93 | K115: 269300 | Z115: 32.43 | AA115: 220520
A119: 45745 | B119: 42.01 | C119: 420100 | D119: 16 | E119: 200000 | X119: 10 | Y119: 125000
D120: 12 | E120: 150000
D122: 16 | E122: 200000
A123: 45746 | F123: 39.26 | G123: 392600 | J123: 29.84 | K123: 298400
...

Sheet FEBRUARI 2025
A1: LAPORAN KONSUMSI BBM KENDARAAN DINAS PT PELINDO DAYA SEJAHTERA
A2: PERIODE FEBRUARI 2025
A3: SUGENG | V3: MAS WAFI
A4: TANGGAL | B4: HANTARAN OPERATOR ITV TPS | L4: OPERASIONAL KEBERSHAN TPS | V4: SAPU JALAN PERAK BARAT | X4: PENYIRAMAN PERAK | Z4: SAPU JALAN (SPMT) | AB4: KEBERSIHAN PERAK | AF4: SAPU JALAN | AH4: GRAND TOTAL
B5: L 1941 OL (L 1873 SB) | D5: L 1941 OL (L 1873 SB) | F5: L 1536 MZ (L 1388 PC) | H5: L 1536 MZ (L 1388 PC) | J5: L 1838 ZB (L 1641 PA) | L5: L 8203 AF | N5: L 9910 BR | P5: L 9910 BR | R5: L 9034 BU | T5: L 9078 BU | V5: pertalite | W5: L 9662 NK | X5: pertamax | Y5: L 9664 NK | Z5: Solar | AA5: AE 8719 SQ/L 8393 LT | AB5: pertalite | AC5: L 8065 TR | AD5: pertalite | AE5: L 1659 U | AF5: pertalite | AG5: L 3098 LG
B6: Pertalite | C6: Rp | D6: Pertamax | E6: Rp | F6: Pertalite | G6: Rp | H6: Pertamax Turbo | I6: Rp | J6: Pertalite | K6: Rp | L6: solar | M6: Rp | N6: solar | O6: Rp | P6: pertamax | Q6: Rp | R6: Pertamina Dex | S6: Rp | T6: Solar | U6: Rp | V6: Liter | W6: Rp | X6: Liter | Y6: Rp | Z6: Liter | AA6: Rp | AB6: Liter | AC6: Rp | AD6: liter | AE6: Rp | AF6: Liter | AG6: Rp
A7: 45689
B8: 27.81 | C8: 278100 | F8: 27.57 | G8: 275700 | J8: 22.79 | K8: 227900 | N8: 52.28 | O8: 355504 | X8: 20 | Y8: 258000
A11: 45690 | B11: 31.06 | C11: 310600 | F11: 29.53 | G11: 295300 | J11: 12.18 | K11: 121800
A15: 45691 | B15: 32.64 | C15: 326400 | F15: 29.92 | G15: 299200 | J15: 17.68 | K15: 176800 | T15: 20 | U15: 136000
A19: 45692 | B19: 27.57 | C19: 275700 | F19: 27.26 | G19: 272600 | J19: 16.04 | K19: 160400 | L19: 20 | M19: 136000 | P19: 20 | Q19: 258000 | AB19: 20 | AC19: 200000
AB20: 25 | AC20: 250000
A23: 45693 | B23: 33.86 | C23: 338600 | F23: 31.29 | G23: 312900 | J23: 19.45 | K23: 194500
A27: 45694 | B27: 29.79 | C27: 297900 | F27: 30.7 | G27: 307000 | J27: 16.53 | K27: 165300 | T27: 20 | U27: 136000 | X27: 20 | Y27: 258000
A31: 45695 | B31: 27.97 | C31: 279700 | F31: 27.39 | G31: 273900 | J31: 16.87 | K31: 168700 | L31: 20 | M31: 136000 | N31: 20 | O31: 136000
A35: 45696 | B35: 20.29 | C35: 202900 | F35: 25.87 | G35: 258700 | J35: 13.89 | K35: 138900
A39: 45697 | B39: 25.93 | C39: 259300 | F39: 23.12 | G39: 231200 | J39: 24.37 | K39: 243700 | N39: 58.66 | O39: 398900
A43: 45698 | B43: 29.54 | C43: 295400 | F43: 30.96 | G43: 309600 | J43: 23.78 | K43: 237800 | L43: 20 | M43: 136000 | P43: 20 | Q43: 258000 | X43: 20 | Y43: 258000 | AB43: 20 | AC43: 200000
AB44: 25 | AC44: 250000
A47: 45699 | B47: 23.82 | C47: 238200 | F47: 23.25 | G47: 232500 | J47: 21.24 | K47: 212400
A51: 45700 | B51: 29.48 | C51: 294800 | F51: 24.54 | G51: 245400 | J51: 19.01 | K51: 190100 | X51: 20 | Y51: 258000
A55: 45701 | B55: 30.57 | C55: 305700 | F55: 25.32 | G55: 253200 | J55: 20.93 | K55: 209300 | L55: 20 | M55: 136000 | Z55: 29.53 | AA55: 200804
A59: 45702 | F59: 11.2 | G59: 112000 | J59: 26.43 | K59: 264300 | N59: 20 | O59: 136000 | T59: 20 | U59: 136000
A63: 45703 | B63: 41.69 | C63: 416900 | F63: 28.83 | G63: 288300 | J63: 17.6 | K63: 176000 | N63: 20 | O63: 136000 | X63: 20 | Y63: 258000
A67: 45704 | B67: 30.2 | C67: 302000 | F67: 25.5 | G67: 255000 | J67: 18.11 | K67: 181100
A71: 45705 | B71: 29.41 | C71: 294100 | F71: 28.17 | G71: 281700 | J71: 21.4 | K71: 214000 | L71: 20 | M71: 136000 | N71: 58.29 | O71: 396370 | P71: 20 | Q71: 258000 | AB71: 20 | AC71: 200000
A75: 45706 | B75: 33.93 | C75: 339300 | F75: 26.37 | G75: 263700 | J75: 25.43 | K75: 254300 | AB75: 25 | AC75: 250000
A79: 45707 | B79: 26.83 | C79: 268300 | F79: 29.41 | G79: 294100 | J79: 22.32 | K79: 223200 | T79: 20 | U79: 136000 | X79: 20 | Y79: 258000
A83: 45708 | B83: 36.22 | C83: 362200 | F83: 29.7 | G83: 297000 | J83: 25.09 | K83: 250900 | L83: 20 | M83: 136000 | N83: 20 | O83: 136000
A87: 45709 | B87: 32.08 | C87: 320800 | F87: 28.72 | G87: 287200 | J87: 18.67 | K87: 186700
A91: 45710 | B91: 34.01 | C91: 340100 | F91: 26.35 | G91: 263500 | J91: 23.04 | K91: 230400 | X91: 20 | Y91: 258000
A95: 45711 | B95: 32.33 | C95: 323300 | F95: 29.07 | G95: 290700 | J95: 23.34 | K95: 233400 | T95: 20 | U95: 136000
A99: 45712 | B99: 37.9 | C99: 379000 | F99: 27.42 | G99: 274200 | J99: 22.25 | K99: 222500 | L99: 20 | M99: 136000 | P99: 20 | Q99: 258000 | AB99: 20 | AC99: 200000
AB100: 10 | AC100: 100000
A103: 45713 | B103: 29.05 | C103: 290500 | F103: 26.25 | G103: 262500 | J103: 16.27 | K103: 162700
T104: 20 | U104: 136000
A107: 45714 | B107: 29.79 | C107: 297900 | F107: 35.33 | G107: 353300 | J107: 19.02 | K107: 190200 | AB107: 10 | AC107: 100000
A111: 45715 | B111: 26.14 | C111: 261400 | F111: 25.87 | G111: 258700 | J111: 18.3 | K111: 183000 | L111: 20 | M111: 136000 | N111: 20 | O111: 136000 | P111: 20 | Q111: 258000 | X111: 20 | Y111: 258000 | AB111: 20 | AC111: 200000
A115: 45716 | B115: 37.83 | C115: 378300 | F115: 35.81 | G115: 358100 | J115: 17.84 | K115: 178400
Z118: 33.64 | AA118: 228752
...

Sheet JANUARI 2025
A1: LAPORAN KONSUMSI BBM KENDARAAN DINAS PT PELINDO DAYA SEJAHTERA
A2: PERIODE JANUARI 2025
A3: SUGENG | V3: MAS WAFI
A4: TANGGAL | B4: HANTARAN OPERATOR ITV TPS | L4: OPERASIONAL KEBERSHAN TPS | V4: SAPU JALAN PERAK BARAT | X4: PENYIRAMAN PERAK | Z4: SAPU JALAN (SPMT) | AB4: KEBERSIHAN PERAK | AF4: SAPU JALAN | AH4: GRAND TOTAL
B5: L 1941 OL (L 1873 SB) | D5: L 1941 OL (L 1873 SB) | F5: L 1536 MZ (L 1388 PC) | H5: L 1536 MZ (L 1388 PC) | J5: L 1838 ZB (L 1641 PA) | L5: L 8203 AF | N5: L 9910 BR | P5: L 9910 BR | R5: L 9034 BU | T5: L 9078 BU | V5: pertalite | W5: L 9662 NK | X5: pertamax | Y5: L 9664 NK | Z5: Solar | AA5: AE 8719 SQ/L 8393 LT | AB5: pertalite | AC5: L 8065 TR | AD5: pertalite | AE5: L 1659 U | AF5: pertalite | AG5: L 3098 LG
B6: Pertalite | C6: Rp | D6: Pertamax | E6: Rp | F6: Pertalite | G6: Rp | H6: Pertamax Turbo | I6: Rp | J6: Pertalite | K6: Rp | L6: solar | M6: Rp | N6: solar | O6: Rp | P6: pertamax | Q6: Rp | R6: Pertamina Dex | S6: Rp | T6: Solar | U6: Rp | V6: Liter | W6: Rp | X6: Liter | Y6: Rp | Z6: Liter | AA6: Rp | AB6: Liter | AC6: Rp | AD6: liter | AE6: Rp | AF6: Liter | AG6: Rp
A7: 45658 | B7: 28.62 | C7: 286200 | F7: 33.39 | G7: 333900 | J7: 24.1 | K7: 241000
A11: 45659 | B11: 29.93 | C11: 299300 | F11: 30.53 | G11: 305300 | J11: 17.26 | K11: 172600 | L11: 20 | M11: 136000 | N11: 20 | O11: 136000 | T11: 20 | U11: 136000
A15: 45660 | B15: 29.35 | C15: 293500 | F15: 26.8 | G15: 268000 | J15: 23.55 | K15: 235500 | P15: 20 | Q15: 250000 | X15: 20 | Y15: 250000 | AF15: 25 | AG15: 250000
V16: 20 | W16: 200000
A19: 45661 | B19: 30.03 | C19: 300300 | F19: 31.65 | G19: 316500 | J19: 23.75 | K19: 237500 | N19: 50.84 | O19: 345750
A23: 45662 | B23: 28.37 | C23: 283700 | F23: 26.47 | G23: 264700 | J23: 20.8 | K23: 208000
A27: 45663 | B27: 29.86 | C27: 298600 | F27: 30.23 | G27: 302300 | J27: 25.98 | K27: 259800 | L27: 20 | M27: 136000 | T27: 20 | U27: 136000
A31: 45664 | B31: 27.47 | C31: 274700 | F31: 34.69 | G31: 346900 | J31: 21.51 | K31: 215100
A35: 45665 | B35: 28.01 | C35: 280100 | F35: 26.6 | G35: 266000 | J35: 23.85 | K35: 238500 | P35: 20 | Q35: 250000
X36: 20 | Y36: 250000
A39: 45666 | B39: 28.03 | C39: 280300 | F39: 31.31 | G39: 313100 | J39: 19.18 | K39: 191800 | L39: 20 | M39: 136000 | T39: 20 | U39: 136000
A43: 45667 | B43: 29.2 | C43: 292000 | J43: 33.19 | K43: 331900 | V43: 20 | W43: 200000
P44: 20 | Q44: 250000 | T44: 48.56 | U44: 330208 | AF44: 20 | AG44: 200000
A47: 45668 | B47: 31.43 | C47: 314300 | F47: 16.94 | G47: 169400 | J47: 29.76 | K47: 297600
A51: 45669 | B51: 32.69 | C51: 326900 | F51: 31.79 | G51: 317900 | J51: 26.99 | K51: 269900 | L51: 20 | M51: 136000
A55: 45670 | B55: 26.57 | C55: 265700 | F55: 25.09 | G55: 250900 | T55: 20 | U55: 136000
A59: 45671 | B59: 28.42 | C59: 284200 | F59: 28.6 | G59: 286000 | J59: 28.2 | K59: 282000 | N59: 20 | O59: 136000 | P59: 20 | Q59: 250000 | AD59: 20 | AE59: 200000
A63: 45672 | B63: 28.64 | C63: 286400 | F63: 29.21 | G63: 292100 | J63: 19.26 | K63: 192600 | L63: 20 | M63: 136000 | N63: 20 | O63: 136000 | X63: 20 | Y63: 250000
A67: 45673 | B67: 38.35 | C67: 383500 | F67: 33.06 | G67: 330600 | J67: 18.12 | K67: 181200 | AF67: 25 | AG67: 250000
A71: 45674 | B71: 28.15 | C71: 281500 | F71: 31.83 | G71: 318300 | J71: 20.43 | K71: 204300 | N71: 20 | O71: 136000
A75: 45675 | B75: 23.85 | C75: 238500 | F75: 29.55 | G75: 295500 | J75: 25.04 | K75: 250400 | L75: 20 | M75: 136000 | T75: 60 | U75: 408000 | X75: 20 | Y75: 250000
A79: 45676 | B79: 28.23 | C79: 282300 | F79: 27.64 | G79: 276400 | J79: 20.35 | K79: 203500 | N79: 20 | O79: 136000
A83: 45677 | B83: 24.78 | C83: 247800 | F83: 26.13 | G83: 261300 | J83: 18.48 | K83: 184800 | Z83: 28.17 | AA83: 191556
A87: 45678 | B87: 36.57 | C87: 365700 | F87: 35.59 | G87: 355900 | J87: 36.7 | K87: 367000 | P87: 20 | Q87: 250000 | AB87: 20 | AC87: 200000
N88: 54.38 | O88: 369784
A91: 45679 | B91: 31.28 | C91: 312800 | F91: 36.88 | G91: 368800 | L91: 20 | M91: 136000
X92: 20 | Y92: 250000
A95: 45680 | B95: 24.9 | C95: 249000 | F95: 31.74 | G95: 317400 | J95: 37.53 | K95: 375300
A99: 45681 | B99: 29.65 | C99: 296500 | F99: 30 | G99: 300000 | J99: 15.33 | K99: 153300 | P99: 20 | Q99: 250000 | T99: 20 | U99: 136000 | X99: 20 | Y99: 250000
A103: 45682 | B103: 28.06 | C103: 280600 | F103: 38.45 | G103: 384500 | J103: 26.65 | K103: 266500 | L103: 20 | M103: 136000
A107: 45683 | B107: 42.4 | C107: 424000 | F107: 35.13 | G107: 351300 | H107: 10.94 | I107: 150000
A111: 45684 | F111: 15.06 | G111: 150600 | J111: 38.44 | K111: 384400
A115: 45685 | F115: 34.12 | G115: 341200 | J115: 18.64 | K115: 186400 | V115: 20 | W115: 200000 | Z115: 32.06 | AA115: 218008
B116: 39.47 | C116: 394700 | AF116: 25 | AG116: 250000
...

Sheet DESEMBER 2024
A1: LAPORAN KONSUMSI BBM KENDARAAN DINAS PT PELINDO DAYA SEJAHTERA
A2: PERIODE DESEMBER 2024
A3: SUGENG | V3: MAS WAFI
A4: TANGGAL | B4: HANTARAN OPERATOR ITV TPS | J4: OPERASIONAL KEBERSHAN TPS | V4: SAPU JALAN PERAK BARAT | X4: PENYIRAMAN PERAK | Z4: SAPU JALAN (SPMT) | AB4: KEBERSIHAN PERAK | AF4: SAPU JALAN | AH4: GRAND TOTAL
B5: L 1941 OL (L 1873 SB) | D5: L 1941 OL (L 1873 SB) | F5: L 1536 MZ (L 1388 PC) | H5: L 1536 MZ (L 1388 PC) | J5: L 1838 ZB (L 1641 PA) | L5: L 8203 AF | N5: L 9910 BR | P5: L 9910 BR | R5: L 9034 BU | T5: L 9078 BU | V5: pertalite | W5: L 9662 NK | X5: pertamax | Y5: L 9664 NK | Z5: Solar | AA5: AE 8719 SQ/L 8393 LT | AB5: pertalite | AC5: L 8065 TR | AD5: pertalite | AE5: L 1659 U | AF5: pertalite | AG5: L 3098 LG
B6: Pertalite | C6: Rp | D6: Pertamax | E6: Rp | F6: Pertalite | G6: Rp | H6: Pertamax | I6: Rp | J6: Pertalite | K6: Rp | L6: solar | M6: Rp | N6: solar | O6: Rp | P6: pertamax | Q6: Rp | R6: Pertamina Dex | S6: Rp | T6: Solar | U6: Rp | V6: Liter | W6: Rp | X6: Liter | Y6: Rp | Z6: Liter | AA6: Rp | AB6: Liter | AC6: Rp | AD6: liter | AE6: Rp | AF6: Liter | AG6: Rp
A7: 45627 | B7: 28.21 | C7: 282100 | F7: 33 | G7: 330000 | J7: 25.98 | K7: 259800 | T7: 38.86 | U7: 264250
A11: 45628 | B11: 40.37 | C11: 403700 | F11: 34.86 | G11: 348600 | J11: 26.46 | K11: 264600
F14: 33.69 | G14: 336900 | J14: 24.39 | K14: 243900
A15: 45629 | B15: 25.92 | C15: 259200 | N15: 20 | O15: 136000 | V15: 20 | W15: 200000
A19: 45630 | B19: 31.06 | C19: 310600 | F19: 23.49 | G19: 234900 | J19: 27.69 | K19: 276900 | L19: 20 | M19: 136000 | T19: 20 | U19: 136000 | X19: 20 | Y19: 242000
P20: 20 | Q20: 242000
A23: 45631 | B23: 27.11 | C23: 271100 | F23: 24.84 | G23: 248400 | J23: 20.51 | K23: 205100 | N23: 20 | O23: 136000 | T23: 20 | U23: 136000
A27: 45632 | B27: 29.83 | C27: 298300 | F27: 33.8 | G27: 338000 | J27: 19.6 | K27: 196000 | V27: 20 | W27: 200000
A31: 45633 | B31: 23.19 | C31: 231900 | F31: 29.85 | G31: 298500 | J31: 20.05 | K31: 200500 | L31: 20 | M31: 136000 | X31: 20 | Y31: 242000
L32: 40 | M32: 272000
A35: 45634 | B35: 34.2 | C35: 342000 | F35: 34.22 | G35: 342200 | J35: 19.6 | K35: 196000
A39: 45635 | B39: 29.98 | C39: 299800 | F39: 34.65 | G39: 346500 | J39: 28.29 | K39: 282900 | V39: 20 | W39: 200000
A43: 45636 | B43: 34.09 | C43: 340900 | F43: 37.16 | G43: 371600 | J43: 33.46 | K43: 334600 | L43: 20 | M43: 136000 | N43: 20 | O43: 136000 | P43: 20 | Q43: 242000 | T43: 20 | U43: 136000
F44: 33.69 | G44: 336900
A47: 45637 | B47: 30.44 | C47: 304400 | F47: 29.9 | G47: 299000 | J47: 36.85 | K47: 368500 | L47: 20 | M47: 136000 | X47: 20 | Y47: 242000
A51: 45638 | B51: 31.72 | C51: 317200 | F51: 26.24 | G51: 262400 | N51: 20 | O51: 136000 | Z51: 26.62 | AA51: 181020
N52: 20 | O52: 136000
A55: 45639 | B55: 26.34 | C55: 263400 | F55: 32.25 | G55: 322500 | J55: 36.22 | K55: 362200 | V55: 20 | W55: 200000 | AD55: 20 | AE55: 200000
A59: 45640 | F59: 32.25 | G59: 322500 | J59: 30 | K59: 300000 | L59: 55.19 | M59: 375292
A63: 45641 | F63: 18.72 | G63: 187200 | J63: 28.8 | K63: 288000
A67: 45642 | F67: 43.07 | G67: 430700 | J67: 37.49 | K67: 374900 | N67: 20 | O67: 136000 | P67: 20 | Q67: 242000
A71: 45643 | J71: 32.34 | K71: 323400 | L71: 20 | M71: 136000 | X71: 20 | Y71: 242000
F72: 40.05 | G72: 400500
A75: 45644 | B75: 26.7 | C75: 267000
A79: 45645 | B79: 37.21 | C79: 372100 | F79: 33.08 | G79: 330800 | L79: 20 | M79: 136000
J80: 22.14 | K80: 221400
A83: 45646 | B83: 40.3 | C83: 403000 | F83: 32.11 | G83: 321100 | N83: 20 | O83: 136000 | P83: 20 | Q83: 242000 | V83: 20 | W83: 200000 | AB83: 25 | AC83: 250000
A87: 45647 | B87: 38.35 | C87: 383500 | F87: 32.18 | G87: 321800 | J87: 37.25 | K87: 372500 | N87: 20 | O87: 136000 | T87: 20 | U87: 136000 | X87: 20 | Y87: 242000
A91: 45648 | B91: 35 | C91: 350000 | F91: 33.12 | G91: 331200 | J91: 26.75 | K91: 267500
N92: 20 | O92: 136000
A95: 45649 | F95: 34.02 | G95: 340200 | J95: 18.9 | K95: 189000 | L95: 20 | M95: 136000
B96: 29.2 | C96: 292000
A99: 45650 | B99: 25.12 | C99: 251200 | J99: 26.98 | K99: 269800 | N99: 20 | O99: 136000 | P99: 20 | Q99: 242000 | T99: 20 | U99: 136000
F100: 30.45 | G100: 304500
...

Sheet NOVEMBER 2024
A1: LAPORAN KONSUMSI BBM KENDARAAN DINAS PT PELINDO DAYA SEJAHTERA
A2: PERIODE NOVEMBER 2024
A3: SUGENG | V3: MAS WAFI
A4: TANGGAL | B4: HANTARAN OPERATOR ITV TPS | J4: OPERASIONAL KEBERSHAN TPS | V4: SAPU JALAN PERAK BARAT | X4: PENYIRAMAN PERAK | Z4: SAPU JALAN (SPMT) | AB4: KEBERSIHAN PERAK | AF4: SAPU JALAN | AH4: GRAND TOTAL
B5: L 1941 OL (L 1873 SB) | D5: L 1941 OL (L 1873 SB) | F5: L 1536 MZ (L 1388 PC) | H5: L 1536 MZ (L 1388 PC) | J5: L 1838 ZB (L 1641 PA) | L5: L 8203 AF | N5: L 9910 BR | P5: L 9910 BR | R5: L 9034 BU | T5: L 9078 BU | V5: pertalite | W5: L 9662 NK | X5: pertamax | Y5: L 9664 NK | Z5: Solar | AA5: AE 8719 SQ/L 8393 LT | AB5: pertalite | AC5: L 8065 TR | AD5: pertalite | AE5: L 1659 U | AF5: pertalite | AG5: L 3098 LG
B6: Pertalite | C6: Rp | D6: Pertamax | E6: Rp | F6: Pertalite | G6: Rp | H6: Pertamax | I6: Rp | J6: Pertalite | K6: Rp | L6: solar | M6: Rp | N6: solar | O6: Rp | P6: pertamax | Q6: Rp | R6: Pertamina Dex | S6: Rp | T6: Solar | U6: Rp | V6: Liter | W6: Rp | X6: Liter | Y6: Rp | Z6: Liter | AA6: Rp | AB6: Liter | AC6: Rp | AD6: liter | AE6: Rp | AF6: Liter | AG6: Rp
A7: 45597 | B7: 35.05 | C7: 350500 | F7: 40.8 | G7: 408000 | J7: 29.98 | K7: 299800 | N7: 20 | O7: 136000 | P7: 20 | Q7: 242000 | AB7: 20 | AC7: 200000 | AF7: 25 | AG7: 250000
X8: 20 | Y8: 242000
A11: 45598 | B11: 34.22 | C11: 342200 | F11: 32.37 | G11: 323700 | J11: 24.17 | K11: 241700 | N11: 40 | O11: 272000
A15: 45599 | B15: 28.12 | C15: 281200 | F15: 29.26 | G15: 292600 | T15: 20 | U15: 136000
J16: 23.19 | K16: 231900
A19: 45600 | B19: 26.86 | C19: 268600 | F19: 34.5 | G19: 345000 | L19: 20 | M19: 136000 | Z19: 21.04 | AA19: 143070
J20: 23.5 | K20: 235000
A23: 45601 | B23: 26.18 | C23: 261800 | F23: 27.99 | G23: 279900
A27: 45602 | B27: 28.38 | C27: 283800 | J27: 38.67 | K27: 386700
F28: 27.45 | G28: 274500 | N28: 20 | O28: 136000 | X28: 20 | Y28: 242000
A31: 45603 | B31: 30.92 | C31: 309200 | F31: 31.76 | G31: 317600 | L31: 20 | M31: 136000
P32: 20 | Q32: 242000 | T32: 20 | U32: 136000 | AD32: 20 | AE32: 200000 | AF32: 20 | AG32: 200000
A35: 45604 | B35: 32.28 | C35: 322800 | F35: 28.02 | G35: 280200 | T35: 20 | U35: 136000
R36: 11.16 | S36: 150000 | X36: 20 | Y36: 242000
A39: 45605 | F39: 29.73 | G39: 297300 | T39: 20 | U39: 136000
J40: 36.06 | K40: 360600 | R40: 11.16 | S40: 150000
R42: 18.6 | S42: 250000
A43: 45606 | F43: 31.78 | G43: 317800 | J43: 10 | K43: 100000 | N43: 20 | O43: 136000 | R43: 11.16 | S43: 150000
R44: 18.6 | S44: 250000
R45: 58.18 | S45: 781940
A47: 45607 | F47: 37.13 | G47: 371300 | J47: 34.92 | K47: 349200 | L47: 20 | M47: 136000 | N47: 20 | O47: 136000
R48: 11.16 | S48: 150000 | X48: 20 | Y48: 242000
A51: 45608 | B51: 38.91 | C51: 389100 | J51: 32.42 | K51: 324200 | T51: 20 | U51: 136000 | Z51: 24.5 | AA51: 166600
R52: 18.6 | S52: 250000 | AD52: 20 | AE52: 200000
A55: 45609 | B55: 34.16 | C55: 341600
J56: 39.11 | K56: 391100 | X56: 20 | Y56: 242000 | Z56: 20 | AA56: 136000
A59: 45610 | B59: 29.53 | C59: 295300 | F59: 37.47 | G59: 374700 | J59: 35.54 | K59: 355400 | L59: 20 | M59: 136000 | T59: 20 | U59: 136000
P61: 20 | Q61: 242000 | X61: 20 | Y61: 242000
A63: 45611 | B63: 30.76 | C63: 307600 | F63: 32.89 | G63: 328900 | J63: 28.95 | K63: 289500 | N63: 20 | O63: 136000
A67: 45612 | F67: 28.94 | G67: 289400
B68: 30.16 | C68: 301600
AD69: 20 | AE69: 200000
A71: 45613 | F71: 39.64 | G71: 396400 | J71: 38.85 | K71: 388500
B72: 39.26 | C72: 392600 | R72: 11.16 | S72: 150000
...

Sheet OKTOBER 2024
A1: LAPORAN KONSUMSI BBM KENDARAAN DINAS PT PELINDO DAYA SEJAHTERA
A2: PERIODE OKTOBER 2024
A3: SUGENG | V3: MAS WAFI
A4: TANGGAL | B4: HANTARAN OPERATOR ITV TPS | J4: OPERASIONAL KEBERSHAN TPS | V4: SAPU JALAN PERAK BARAT | X4: PENYIRAMAN PERAK | Z4: SAPU JALAN (SPMT) | AB4: KEBERSIHAN PERAK | AF4: SAPU JALAN | AH4: GRAND TOTAL
B5: L 1941 OL (L 1873 SB) | D5: L 1941 OL (L 1873 SB) | F5: L 1536 MZ (L 1388 PC) | H5: L 1536 MZ (L 1388 PC) | J5: L 1838 ZB (L 1641 PA) | L5: L 8203 AF | N5: L 9910 BR | P5: L 9910 BR | R5: L 9034 BU | T5: L 9078 BU | V5: pertalite | W5: L 9662 NK | X5: pertamax | Y5: L 9664 NK | Z5: Solar | AA5: AE 8719 SQ/L 8393 LT | AB5: pertalite | AC5: L 8065 TR | AD5: pertalite | AE5: L 1659 U | AF5: pertalite | AG5: L 3098 LG
B6: Pertalite | C6: Rp | D6: Pertamax | E6: Rp | F6: Pertalite | G6: Rp | H6: Pertamax | I6: Rp | J6: Pertalite | K6: Rp | L6: solar | M6: Rp | N6: solar | O6: Rp | P6: pertamax | Q6: Rp | R6: Pertamina Dex | S6: Rp | T6: Solar | U6: Rp | V6: Liter | W6: Rp | X6: Liter | Y6: Rp | Z6: Liter | AA6: Rp | AB6: Liter | AC6: Rp | AD6: liter | AE6: Rp | AF6: Liter | AG6: Rp
A7: 45566 | B7: 34.07 | C7: 340700 | F7: 18.42 | G7: 184200 | J7: 25.71 | K7: 257100 | N7: 20 | O7: 136000 | V7: 20 | W7: 200000 | X7: 21.4 | Y7: 259000
A11: 45567 | B11: 31.54 | C11: 315400 | F11: 30.27 | G11: 302700 | J11: 19.49 | K11: 194900 | L11: 20 | M11: 136000 | Z11: 24.87 | AA11: 169120 | AD11: 20 | AE11: 200000
A15: 45568 | B15: 24.85 | C15: 248500 | F15: 36.88 | G15: 368800 | J15: 19.24 | K15: 192400 | T15: 20 | U15: 136000 | X15: 20 | Y15: 242000
